Workbook
Name Data_Description_and_Highlights: Analysis!$F$31
Name Slicer_type: #N/A

Sheet Sheet3
A1: show_id | B1: type | C1: title | D1: director | E1: cast | F1: country | G1: date_added | H1: release_year | I1: rating | J1: duration | K1: listed_in | L1: description
A2: s8190 | B2: TV Show | C2: The Andy Griffith Show | E2: Andy Griffith, Ron Howard, Don Knotts, Frances Bavier, Howard McNear, Hope Summers | F2: United States | G2: July 1, 2017 | H2: 1967 | I2: TV-G | J2: 8 Seasons | K2: Classic & Cult TV, TV Comedies | L2: Homespun humor and easygoing Sheriff Andy Taylor are at the center of this nostalgic look at Mayberry, a small town filled with lovable characters.

Sheet Dashboard

Sheet Pivot Table
A3: Percentage of type | E3: Total number of release of movies and shows per year | J3: Ratings of movies and TV shows
A5: TYPE | B5: % of TYPE | E5: Year | F5: No of release of movies & shows | J5: Rating | K5: Count of Rating | O5: Top 5 actors of movies and TV shows | R5: Top 10 countries of movies and TV shows
A6: Movie | B6: 1 | E6: 2017 | F6: 767 | J6: TV-MA | K6: 2062
A7: Grand Total | B7: 1 | E7: Movie | F7: 767 | J7: TV-14 | K7: 1427 | O7: Actors | P7: Count of Actor names | R7: Country | S7: Count of country | AD7: Top 10 genre of movies and TV shows
E8: 2018 | F8: 767 | J8: R | K8: 797 | O8: Vatsal Dubey, Julie Tejwani, Rupa Bhimani, Jigna Bhardwaj, Rajesh Kava, Mousam, Swapnil | P8: 13 | R8: United States | S8: 2058
E9: Movie | F9: 767 | J9: TV-PG | K9: 540 | O9: Samuel West | P9: 10 | R9: India | S9: 893 | AD9: Genre | AE9: Count of Genre
E10: 2016 | F10: 658 | J10: PG-13 | K10: 490 | O10: Jeff Dunham | P10: 7 | R10: United Kingdom | S10: 206 | AD10: Stand-Up Comedy | AE10: 334 | BJ10: Top 10 directors on Netflix.
E11: Movie | F11: 658 | J11: PG | K11: 287 | O11: Craig Sechler | P11: 6 | R11: Canada | S11: 122 | AD11: Dramas, International Movies, Romantic Movies | AE11: 180
E12: 2019 | F12: 633 | J12: TV-Y7 | K12: 139 | O12: Kevin Hart | P12: 6 | R12: Spain | S12: 97 | AD12: Dramas, International Movies | AE12: 362 | BJ12: Directors | BK12: Count of director
E13: Movie | F13: 633 | J13: TV-Y | K13: 131 | O13: David Attenborough | P13: 5 | R13: Egypt | S13: 92 | AD13: Dramas, Independent Movies, International Movies | AE13: 252 | BJ13: Rajiv Chilaka | BK13: 19
E14: 2020 | F14: 517 | J14: TV-G | K14: 126 | O14: Michela Luci, Jamie Watson, Eric Peterson, Anna Claire Bartlam, Nicolas Aqui, Cory Doran, Julie Lemieux, Derek McGrath | P14: 5 | R14: Nigeria | S14: 86 | AD14: Documentaries, International Movies | AE14: 186 | BJ14: RaÃºl Campos, Jan Suter | BK14: 18
E15: Movie | F15: 517 | J15: NR | K15: 75 | O15: Jim Gaffigan | P15: 5 | R15: Indonesia | S15: 77 | AD15: Documentaries | AE15: 359 | BJ15: Suhas Kadav | BK15: 16
E16: 2015 | F16: 398 | J16: G | K16: 41 | O16: Bill Burr | P16: 5 | R16: Turkey | S16: 76 | AD16: Comedies, International Movies | AE16: 176 | BJ16: Marcus Raboy | BK16: 16
E17: Movie | F17: 398 | J17: TV-Y7-FV | K17: 5 | O17: David Spade, London Hughes, Fortune Feimster | P17: 5 | R17: Japan | S17: 76 | AD17: Comedies, Dramas, International Movies | AE17: 274 | BJ17: Jay Karas | BK17: 14
E18: 2021 | F18: 277 | J18: UR | K18: 3 | O18: Iliza Shlesinger | P18: 5 | R18: Grand Total | S18: 3783 | AD18: Children & Family Movies, Comedies | AE18: 201 | BJ18: Cathy Garcia-Molina | BK18: 13
E19: Movie | F19: 277 | J19: NC-17 | K19: 3 | O19: Grand Total | P19: 72 | AD19: Children & Family Movies | AE19: 215 | BJ19: Youssef Chahine | BK19: 12
E20: 2014 | F20: 264 | J20: (blank) | K20: 2 | AD20: Grand Total | AE20: 2539 | BJ20: Jay Chapman | BK20: 12
E21: Movie | F21: 264 | J21: 66 min | K21: 1 | BJ21: Martin Scorsese | BK21: 12
E22: 2013 | F22: 225 | J22: 84 min | K22: 1 | BJ22: Steven Spielberg | BK22: 11
E23: Movie | F23: 225 | J23: 74 min | K23: 1 | BJ23: Grand Total | BK23: 143
E24: 2012 | F24: 173 | J24: Grand Total | K24: 6131
E25: Movie | F25: 173
E26: Grand Total | F26: 4679

Sheet Dataset
A1: show_id | B1: type | C1: title | D1: director | E1: cast | F1: country | G1: date_added | H1: release_year | I1: rating | J1: duration | K1: listed_in | L1: description
A2: s1 | B2: Movie | C2: Dick Johnson Is Dead | D2: Kirsten Johnson | F2: United States | G2: September 25, 2021 | H2: 2020 | I2: PG-13 | J2: 90 min | K2: Documentaries | L2: As her father nears the end of his life, filmmaker Kirsten Johnson stages his death in inventive and comical ways to help them both face the inevitable.
A3: s2 | B3: TV Show | C3: Blood & Water | E3: Ama Qamata, Khosi Ngema, Gail Mabalane, Thabang Molaba, Dillon Windvogel, Natasha Thahane, Arno Greeff, Xolile Tshabalala, Getmore Sithole, Cindy Mahlangu, Ryle De Morny, Greteli Fincham, Sello Maake Ka-Ncube, Odwa Gwanya, Mekaila Mathys, Sandi Schultz, Duane Williams, Shamilla Miller, Patrick Mofokeng | F3: South Africa | G3: September 24, 2021 | H3: 2021 | I3: TV-MA | J3: 2 Seasons | K3: International TV Shows, TV Dramas, TV Mysteries | L3: After crossing paths at a party, a Cape Town teen sets out to prove whether a private-school swimming star is her sister who was abducted at birth.
A4: s3 | B4: TV Show | C4: Ganglands | D4: Julien Leclercq | E4: Sami Bouajila, Tracy Gotoas, Samuel Jouy, Nabiha Akkari, Sofia Lesaffre, Salim Kechiouche, Noureddine Farihi, Geert Van Rampelberg, Bakary Diombera | G4: September 24, 2021 | H4: 2021 | I4: TV-MA | J4: 1 Season | K4: Crime TV Shows, International TV Shows, TV Action & Adventure | L4: To protect his family from a powerful drug lord, skilled thief Mehdi and his expert team of robbers are pulled into a violent and deadly turf war.
A5: s4 | B5: TV Show | C5: Jailbirds New Orleans | G5: September 24, 2021 | H5: 2021 | I5: TV-MA | J5: 1 Season | K5: Docuseries, Reality TV | L5: Feuds, flirtations and toilet talk go down among the incarcerated women at the Orleans Justice Center in New Orleans on this gritty reality series.
A6: s5 | B6: TV Show | C6: Kota Factory | E6: Mayur More, Jitendra Kumar, Ranjan Raj, Alam Khan, Ahsaas Channa, Revathi Pillai, Urvi Singh, Arun Kumar | F6: India | G6: September 24, 2021 | H6: 2021 | I6: TV-MA | J6: 2 Seasons | K6: International TV Shows, Romantic TV Shows, TV Comedies | L6: In a city of coaching centers known to train Indiaâ€™s finest collegiate minds, an earnest but unexceptional student and his friends navigate campus life.
A7: s6 | B7: TV Show | C7: Midnight Mass | D7: Mike Flanagan | E7: Kate Siegel, Zach Gilford, Hamish Linklater, Henry Thomas, Kristin Lehman, Samantha Sloyan, Igby Rigney, Rahul Kohli, Annarah Cymone, Annabeth Gish, Alex Essoe, Rahul Abburi, Matt Biedel, Michael Trucco, Crystal Balint, Louis Oliver | G7: September 24, 2021 | H7: 2021 | I7: TV-MA | J7: 1 Season | K7: TV Dramas, TV Horror, TV Mysteries | L7: The arrival of a charismatic young priest brings glorious miracles, ominous mysteries and renewed religious fervor to a dying town desperate to believe.
A8: s7 | B8: Movie | C8: My Little Pony: A New Generation | D8: Robert Cullen, JosÃ© Luis Ucha | E8: Vanessa Hudgens, Kimiko Glenn, James Marsden, Sofia Carson, Liza Koshy, Ken Jeong, Elizabeth Perkins, Jane Krakowski, Michael McKean, Phil LaMarr | G8: September 24, 2021 | H8: 2021 | I8: PG | J8: 91 min | K8: Children & Family Movies | L8: Equestria's divided. But a bright-eyed hero believes Earth Ponies, Pegasi and Unicorns should be pals â€” and, hoof to heart, sheâ€™s determined to prove it.
A9: s8 | B9: Movie | C9: Sankofa | D9: Haile Gerima | E9: Kofi Ghanaba, Oyafunmike Ogunlano, Alexandra Duah, Nick Medley, Mutabaruka, Afemo Omilami, Reggie Carter, Mzuri | F9: United States, Ghana, Burkina Faso, United Kingdom, Germany, Ethiopia | G9: September 24, 2021 | H9: 1993 | I9: TV-MA | J9: 125 min | K9: Dramas, Independent Movies, International Movies | L9: On a photo shoot in Ghana, an American model slips back in time, becomes enslaved on a plantation and bears witness to the agony of her ancestral past.
A10: s9 | B10: TV Show | C10: The Great British Baking Show | D10: Andy Devonshire | E10: Mel Giedroyc, Sue Perkins, Mary Berry, Paul Hollywood | F10: United Kingdom | G10: September 24, 2021 | H10: 2021 | I10: TV-14 | J10: 9 Seasons | K10: British TV Shows, Reality TV | L10: A talented batch of amateur bakers face off in a 10-week competition, whipping up their best dishes in the hopes of being named the U.K.'s best.
A11: s10 | B11: Movie | C11: The Starling | D11: Theodore Melfi | E11: Melissa McCarthy, Chris O'Dowd, Kevin Kline, Timothy Olyphant, Daveed Diggs, Skyler Gisondo, Laura Harrier, Rosalind Chao, Kimberly Quinn, Loretta Devine, Ravi Kapoor | F11: United States | G11: September 24, 2021 | H11: 2021 | I11: PG-13 | J11: 104 min | K11: Comedies, Dramas | L11: A woman adjusting to life after a loss contends with a feisty bird that's taken over her garden â€” and a husband who's struggling to find a way forward.
A12: s11 | B12: TV Show | C12: Vendetta: Truth, Lies and The Mafia | G12: September 24, 2021 | H12: 2021 | I12: TV-MA | J12: 1 Season | K12: Crime TV Shows, Docuseries, International TV Shows | L12: Sicily boasts a bold "Anti-Mafia" coalition. But what happens when those trying to bring down organized crime are accused of being criminals themselves?
A13: s12 | B13: TV Show | C13: Bangkok Breaking | D13: Kongkiat Komesiri | E13: Sukollawat Kanarot, Sushar Manaying, Pavarit Mongkolpisit, Sahajak Boonthanakit, Suthipongse Thatphithakkul, Bhasaworn Bawronkirati, Daweerit Chullasapya, Waratthaya Wongchayaporn, Kittiphoom Wongpentak, Abhicha Thanachanun, Nophand Boonyai, Kittipong Khamsat, Arisara Wongchalee, Jaytiya Naiwattanakul, Pantipa Arunwattanachai, Panupan Jantanawong, Kungtap Saelim, Phumphat Chartsuriyakiat, Issara Veranitinunt, Keerati Sivakuae, Panjai Sirisuwan, Supranee Charoenpol, Suda Chuenban, Visaka Banhansupavat, Pitchatorn Santinatornkul | G13: September 23, 2021 | H13: 2021 | I13: TV-MA | J13: 1 Season | K13: Crime TV Shows, International TV Shows, TV Action & Adventure | L13: Struggling to earn a living in Bangkok, a man joins an emergency rescue service and realizes he must unravel a citywide conspiracy.
A14: s13 | B14: Movie | C14: Je Suis Karl | D14: Christian Schwochow | E14: Luna Wedler, Jannis NiewÃ¶hner, Milan Peschel, Edin HasanoviÄ‡, Anna FialovÃ¡, Marlon Boess, Victor Boccard, Fleur Geffrier, Aziz Dyab, MÃ©lanie FouchÃ©, Elizaveta MaximovÃ¡ | F14: Germany, Czech Republic | G14: September 23, 2021 | H14: 2021 | I14: TV-MA | J14: 127 min | K14: Dramas, International Movies | L14: After most of her family is murdered in a terrorist bombing, a young woman is unknowingly lured into joining the very group that killed them.
A15: s14 | B15: Movie | C15: Confessions of an Invisible Girl | D15: Bruno Garotti | E15: Klara Castanho, Lucca Picon, JÃºlia Gomes, Marcus Bessa, Kiria Malheiros, Fernanda Concon, Gabriel Lima, Caio Cabral, Leonardo Cidade, Jade Cardozo | G15: September 22, 2021 | H15: 2021 | I15: TV-PG | J15: 91 min | K15: Children & Family Movies, Comedies | L15: When the clever but socially-awkward TetÃª joins a new school, she'll do anything to fit in. But the queen bee among her classmates has other ideas.
A16: s15 | B16: TV Show | C16: Crime Stories: India Detectives | G16: September 22, 2021 | H16: 2021 | I16: TV-MA | J16: 1 Season | K16: British TV Shows, Crime TV Shows, Docuseries | L16: Cameras following Bengaluru police on the job offer a rare glimpse into the complex and challenging inner workings of four major crime investigations.
A17: s16 | B17: TV Show | C17: Dear White People | E17: Logan Browning, Brandon P. Bell, DeRon Horton, Antoinette Robertson, John Patrick Amedori, Ashley Blaine Featherson, Marque Richardson, Giancarlo Esposito | F17: United States | G17: September 22, 2021 | H17: 2021 | I17: TV-MA | J17: 4 Seasons | K17: TV Comedies, TV Dramas | L17: Students of color navigate the daily slights and slippery politics of life at an Ivy League college that's not nearly as "post-racial" as it thinks.
A18: s17 | B18: Movie | C18: Europe's Most Dangerous Man: Otto Skorzeny in Spain | D18: Pedro de Echave GarcÃ­a, Pablo AzorÃ­n Williams | G18: September 22, 2021 | H18: 2020 | I18: TV-MA | J18: 67 min | K18: Documentaries, International Movies | L18: Declassified documents reveal the post-WWII life of Otto Skorzeny, a close Hitler ally who escaped to Spain and became an adviser to world presidents.
A19: s18 | B19: TV Show | C19: Falsa identidad | E19: Luis Ernesto Franco, Camila Sodi, Sergio Goyri, Samadhi Zendejas, Eduardo YÃ¡Ã±ez, Sonya Smith, Alejandro Camacho, Azela Robinson, Uriel del Toro, GÃ©raldine BazÃ¡n, Gabriela Roel, Marcus Ornellas | F19: Mexico | G19: September 22, 2021 | H19: 2020 | I19: TV-MA | J19: 2 Seasons | K19: Crime TV Shows, Spanish-Language TV Shows, TV Dramas | L19: Strangers Diego and Isabel flee their home in Mexico and pretend to be a married couple to escape his drug-dealing enemies and her abusive husband.
A20: s19 | B20: Movie | C20: Intrusion | D20: Adam Salky | E20: Freida Pinto, Logan Marshall-Green, Robert John Burke, Megan Elisabeth Kelly, Sarah Minnich, Hayes Hargrove, Mark Sivertsen, Brandon Fierro, Antonio Valles, Clint Obenchain | G20: September 22, 2021 | H20: 2021 | I20: TV-14 | J20: 94 min | K20: Thrillers | L20: After a deadly home invasion at a coupleâ€™s new dream house, the traumatized wife searches for answers â€” and learns the real danger is just beginning.
A21: s20 | B21: TV Show | C21: Jaguar | E21: Blanca SuÃ¡rez, IvÃ¡n Marcos, Ã“scar Casas, AdriÃ¡n Lastra, Francesc Garrido, Stefan Weinert, Julia MÃ¶ller, Alicia Chojnowski | G21: September 22, 2021 | H21: 2021 | I21: TV-MA | J21: 1 Season | K21: International TV Shows, Spanish-Language TV Shows, TV Action & Adventure | L21: In the 1960s, a Holocaust survivor joins a group of self-trained spies who seek justice against Nazis fleeing to Spain to hide after WWII.
A22: s21 | B22: TV Show | C22: Monsters Inside: The 24 Faces of Billy Milligan | D22: Olivier Megaton | G22: September 22, 2021 | H22: 2021 | I22: TV-14 | J22: 1 Season | K22: Crime TV Shows, Docuseries, International TV Shows | L22: In the late 1970s, an accused serial rapist claims multiple personalities control his behavior, setting off a legal odyssey that captivates America.
A23: s22 | B23: TV Show | C23: Resurrection: Ertugrul | E23: Engin Altan DÃ¼zyatan, Serdar GÃ¶khan, HÃ¼lya Darcan, Kaan TaÅŸaner, Esra BilgiÃ§, Osman Soykut, Serdar Deniz, Cengiz CoÅŸkun, Reshad Strik, Hande SubaÅŸÄ± | F23: Turkey | G23: September 22, 2021 | H23: 2018 | I23: TV-14 | J23: 5 Seasons | K23: International TV Shows, TV Action & Adventure, TV Dramas | L23: When a good deed unwittingly endangers his clan, a 13th-century Turkish warrior agrees to fight a sultan's enemies in exchange for new tribal land.
A24: s23 | B24: Movie | C24: Avvai Shanmughi | D24: K.S. Ravikumar | E24: Kamal Hassan, Meena, Gemini Ganesan, Heera Rajgopal, Nassar, S.P. Balasubrahmanyam | G24: September 21, 2021 | H24: 1996 | I24: TV-PG | J24: 161 min | K24: Comedies, International Movies | L24: Newly divorced and denied visitation rights with his daughter, a doting father disguises himself as a gray-haired nanny in order to spend time with her.
A25: s24 | B25: Movie | C25: Go! Go! Cory Carson: Chrissy Takes the Wheel | D25: Alex Woo, Stanley Moore | E25: Maisie Benson, Paul Killam, Kerry Gudjohnsen, AC Lim | G25: September 21, 2021 | H25: 2021 | I25: TV-Y | J25: 61 min | K25: Children & Family Movies | L25: From arcade games to sled days and hiccup cures, Cory Carsonâ€™s curious little sister Chrissy speeds off on her own for fun and adventure all over town!
A26: s25 | B26: Movie | C26: Jeans | D26: S. Shankar | E26: Prashanth, Aishwarya Rai Bachchan, Sri Lakshmi, Nassar | F26: India | G26: September 21, 2021 | H26: 1998 | I26: TV-14 | J26: 166 min | K26: Comedies, International Movies, Romantic Movies | L26: When the father of the man she loves insists that his twin sons marry twin sisters, a woman creates an alter ego that might be a bit too convincing.
A27: s26 | B27: TV Show | C27: Love on the Spectrum | E27: Brooke Satchwell | F27: Australia | G27: September 21, 2021 | H27: 2021 | I27: TV-14 | J27: 2 Seasons | K27: Docuseries, International TV Shows, Reality TV | L27: Finding love can be hard for anyone. For young adults on the autism spectrum, exploring the unpredictable world of dating is even more complicated.
A28: s27 | B28: Movie | C28: Minsara Kanavu | D28: Rajiv Menon | E28: Arvind Swamy, Kajol, Prabhu Deva, Nassar, S.P. Balasubrahmanyam, Girish Karnad | G28: September 21, 2021 | H28: 1997 | I28: TV-PG | J28: 147 min | K28: Comedies, International Movies, Music & Musicals | L28: A tangled love triangle ensues when a man falls for a woman studying to become a nun â€” and she falls for the friend he enlists to help him pursue her.
A29: s28 | B29: Movie | C29: Grown Ups | D29: Dennis Dugan | E29: Adam Sandler, Kevin James, Chris Rock, David Spade, Rob Schneider, Salma Hayek, Maria Bello, Maya Rudolph, Colin Quinn, Tim Meadows, Joyce Van Patten | F29: United States | G29: September 20, 2021 | H29: 2010 | I29: PG-13 | J29: 103 min | K29: Comedies | L29: Mourning the loss of their beloved junior high basketball coach, five middle-aged pals reunite at a lake house and rediscover the joys of being a kid.
A30: s29 | B30: Movie | C30: Dark Skies | D30: Scott Stewart | E30: Keri Russell, Josh Hamilton, J.K. Simmons, Dakota Goyo, Kadan Rockett, L.J. Benet, Rich Hutchman, Myndy Crist, Annie Thurman, Jake Brennan | F30: United States | G30: September 19, 2021 | H30: 2013 | I30: PG-13 | J30: 97 min | K30: Horror Movies, Sci-Fi & Fantasy | L30: A familyâ€™s idyllic suburban life shatters when an alien force invades their home, and as they struggle to convince others of the deadly threat.
A31: s30 | B31: Movie | C31: Paranoia | D31: Robert Luketic | E31: Liam Hemsworth, Gary Oldman, Amber Heard, Harrison Ford, Lucas Till, Embeth Davidtz, Julian McMahon, Josh Holloway, Richard Dreyfuss, Angela Sarafyan | F31: United States, India, France | G31: September 19, 2021 | H31: 2013 | I31: PG-13 | J31: 106 min | K31: Thrillers | L31: Blackmailed by his company's CEO, a low-level employee finds himself forced to spy on the boss's rival and former mentor.
A32: s31 | B32: Movie | C32: Ankahi Kahaniya | D32: Ashwiny Iyer Tiwari, Abhishek Chaubey, Saket Chaudhary | E32: Abhishek Banerjee, Rinku Rajguru, Delzad Hiwale, Kunal Kapoor, Zoya Hussain, Nikhil Dwivedi, Palomi Ghosh | G32: September 17, 2021 | H32: 2021 | I32: TV-14 | J32: 111 min | K32: Dramas, Independent Movies, International Movies | L32: As big city life buzzes around them, lonely souls discover surprising sources of connection and companionship in three tales of love, loss and longing.
A33: s32 | B33: TV Show | C33: Chicago Party Aunt | E33: Lauren Ash, Rory O'Malley, RuPaul Charles, Jill Talley, Ike Barinholtz, Jon Barinholtz, Matthew Craig, Bob Odenkirk, Mike Hagerty, Katie Rich, Chris Witaske | G33: September 17, 2021 | H33: 2021 | I33: TV-MA | J33: 1 Season | K33: TV Comedies | L33: Chicago Party Aunt Diane is an idolized troublemaker with a talent for avoiding adulthood â€” and a soft spot for her soul-searching nephew.
A34: s33 | B34: TV Show | C34: Sex Education | E34: Asa Butterfield, Gillian Anderson, Ncuti Gatwa, Emma Mackey, Connor Swindells, Kedar Williams-Stirling, Alistair Petrie | F34: United Kingdom | G34: September 17, 2021 | H34: 2020 | I34: TV-MA | J34: 3 Seasons | K34: British TV Shows, International TV Shows, TV Comedies | L34: Insecure Otis has all the answers when it comes to sex advice, thanks to his therapist mom. So rebel Maeve proposes a school sex-therapy clinic.
A35: s34 | B35: TV Show | C35: Squid Game | E35: Lee Jung-jae, Park Hae-soo, Wi Ha-jun, Oh Young-soo, Jung Ho-yeon, Heo Sung-tae, Kim Joo-ryoung, Tripathi Anupam, You Seong-joo, Lee You-mi | G35: September 17, 2021 | H35: 2021 | I35: TV-MA | J35: 1 Season | K35: International TV Shows, TV Dramas, TV Thrillers | L35: Hundreds of cash-strapped players accept a strange invitation to compete in children's games. Inside, a tempting prize awaits â€” with deadly high stakes.
A36: s35 | B36: TV Show | C36: Tayo and Little Wizards | E36: Dami Lee, Jason Lee, Bommie Catherine Han, Jennifer Waescher, Nancy Kim | G36: September 17, 2021 | H36: 2020 | I36: TV-Y7 | J36: 1 Season | K36: Kids' TV | L36: Tayo speeds into an adventure when his friends get kidnapped by evil magicians invading their city in search of a magical gemstone.
A37: s36 | B37: Movie | C37: The Father Who Moves Mountains | D37: Daniel Sandu | E37: Adrian Titieni, Elena Purea, Judith State, Valeriu AndriuÈ›Äƒ, Tudor Smoleanu, Virgil Aioanei, Radu Botar, Petronela Grigorescu, Bogdan Nechifor, Cristian Bota | G37: September 17, 2021 | H37: 2021 | I37: TV-MA | J37: 110 min | K37: Dramas, International Movies, Thrillers | L37: When his son goes missing during a snowy hike in the mountains, a retired intelligence officer will stop at nothing â€” and risk everything â€” to find him.
A38: s37 | B38: Movie | C38: The Stronghold | D38: CÃ©dric Jimenez | E38: Gilles Lellouche, Karim Leklou, FranÃ§ois Civil, AdÃ¨le Exarchopoulos, Kenza Fortas, Cyril Lecomte, MichaÃ«l Abiteboul, Idir Azougli, Vincent Darmuzey, Jean-Yves Berteloot | G38: September 17, 2021 | H38: 2021 | I38: TV-MA | J38: 105 min | K38: Action & Adventure, Dramas, International Movies | L38: Tired of the small-time grind, three Marseille cops get a chance to bust a major drug network. But lines blur when a key informant makes a big ask.
A39: s38 | B39: TV Show | C39: Angry Birds | E39: Antti PÃ¤Ã¤kkÃ¶nen, HeljÃ¤ Heikkinen, Lynne Guaglione, Pasi Ruohonen, Rauno Ahonen | F39: Finland | G39: September 16, 2021 | H39: 2018 | I39: TV-Y7 | J39: 1 Season | K39: Kids' TV, TV Comedies | L39: Birds Red, Chuck and their feathered friends have lots of adventures while guarding eggs in their nest that pesky pigs keep trying to steal.
A40: s39 | B40: Movie | C40: Birth of the Dragon | D40: George Nolfi | E40: Billy Magnussen, Ron Yuan, Qu Jingjing, Terry Chen, Vanness Wu, Jin Xing, Philip Ng, Xia Yu, Yu Xia | F40: China, Canada, United States | G40: September 16, 2021 | H40: 2017 | I40: PG-13 | J40: 96 min | K40: Action & Adventure, Dramas | L40: A young Bruce Lee angers kung fu traditionalists by teaching outsiders, leading to a showdown with a Shaolin master in this film based on real events.
...

Sheet Analysis
A5: DATA ANALYSIS
J7: Total no. of Movies | L7: =COUNTIF(Dataset!B:B,"Movie") -> 6131
J8: Total no. of Shows | L8: =COUNTIF(Dataset!B:B,"TV Show") -> 2676
J9: Total | L9: =SUM(L7+L8) -> 8807
A18: LOOKUP
F20: show_id | G20: type | H20: title | I20: director | J20: cast | K20: country | L20: date_added | M20: release_year | N20: rating | O20: duration | P20: listed_in | Q20: description
F21: s48 | G21: =VLOOKUP($F21,Dataset!$A$1:$L$8808,MATCH(Analysis!G$20,Dataset!$A$1:$L$1,0),0) -> TV Show | H21: =VLOOKUP($F21,Dataset!$A$1:$L$8808,MATCH(Analysis!H$20,Dataset!$A$1:$L$1,0),0) -> The Smart Money Woman | I21: =VLOOKUP($F21,Dataset!$A$1:$L$8808,MATCH(Analysis!I$20,Dataset!$A$1:$L$1,0),0) -> Bunmi Ajakaiye | J21: =VLOOKUP($F21,Dataset!$A$1:$L$8808,MATCH(Analysis!J$20,Dataset!$A$1:$L$1,0),0) -> Osas Ighodaro, Ini Dima-Okojie, Kemi Lala Akindoju, Toni Tones, Ebenezer Eno, Eso Okolocha DIke, Patrick Diabuah, Karibi Fubara, Temisan Emmanuel, Timini Egbuson | K21: =VLOOKUP($F21,Dataset!$A$1:$L$8808,MATCH(Analysis!K$20,Dataset!$A$1:$L$1,0),0) -> 0 | L21: =VLOOKUP($F21,Dataset!$A$1:$L$8808,MATCH(Analysis!L$20,Dataset!$A$1:$L$1,0),0) -> September 16, 2021 | M21: =VLOOKUP($F21,Dataset!$A$1:$L$8808,MATCH(Analysis!M$20,Dataset!$A$1:$L$1,0),0) -> 2020 | N21: =VLOOKUP($F21,Dataset!$A$1:$L$8808,MATCH(Analysis!N$20,Dataset!$A$1:$L$1,0),0) -> TV-MA | ... Q21: =VLOOKUP($F21,Dataset!$A$1:$L$8808,MATCH(Analysis!Q$20,Dataset!$A$1:$L$1,0),0) -> Five glamorous millennials strive for success as they juggle careers, finances, love and friendships. Based on Arese Ugwu's 2016 best-selling novel.
F22: s4210 | G22: =VLOOKUP($F22,Dataset!$A$1:$L$8808,MATCH(Analysis!G$20,Dataset!$A$1:$L$1,0),0) -> Movie | H22: =VLOOKUP($F22,Dataset!$A$1:$L$8808,MATCH(Analysis!H$20,Dataset!$A$1:$L$1,0),0) -> Next Enti? | I22: =VLOOKUP($F22,Dataset!$A$1:$L$8808,MATCH(Analysis!I$20,Dataset!$A$1:$L$1,0),0) -> Kunal Kohli | J22: =VLOOKUP($F22,Dataset!$A$1:$L$8808,MATCH(Analysis!J$20,Dataset!$A$1:$L$1,0),0) -> Navdeep, Larissa Bonesi, Sarathbabu, Tamannaah Bhatia, Sundeep Kishan, Poonam Kaur | K22: =VLOOKUP($F22,Dataset!$A$1:$L$8808,MATCH(Analysis!K$20,Dataset!$A$1:$L$1,0),0) -> India | L22: =VLOOKUP($F22,Dataset!$A$1:$L$8808,MATCH(Analysis!L$20,Dataset!$A$1:$L$1,0),0) -> 43474 | M22: =VLOOKUP($F22,Dataset!$A$1:$L$8808,MATCH(Analysis!M$20,Dataset!$A$1:$L$1,0),0) -> 2018 | N22: =VLOOKUP($F22,Dataset!$A$1:$L$8808,MATCH(Analysis!N$20,Dataset!$A$1:$L$1,0),0) -> TV-14 | ... Q22: =VLOOKUP($F22,Dataset!$A$1:$L$8808,MATCH(Analysis!Q$20,Dataset!$A$1:$L$1,0),0) -> Clashing views on intimacy lead a couple to go their separate ways to reflect on commitment and companionship, before suddenly crossing paths again.
F23: s5578 | G23: =VLOOKUP($F23,Dataset!$A$1:$L$8808,MATCH(Analysis!G$20,Dataset!$A$1:$L$1,0),0) -> Movie | H23: =VLOOKUP($F23,Dataset!$A$1:$L$8808,MATCH(Analysis!H$20,Dataset!$A$1:$L$1,0),0) -> 100 Meters | I23: =VLOOKUP($F23,Dataset!$A$1:$L$8808,MATCH(Analysis!I$20,Dataset!$A$1:$L$1,0),0) -> Marcel Barrena | J23: =VLOOKUP($F23,Dataset!$A$1:$L$8808,MATCH(Analysis!J$20,Dataset!$A$1:$L$1,0),0) -> Dani Rovira, Karra Elejalde, Alexandra JimÃ©nez, David Verdaguer, Clara Segura, Alba Ribas, Bruno Bergonzini, Ricardo Pereira, Manuela Couto, Marc Balaguer | K23: =VLOOKUP($F23,Dataset!$A$1:$L$8808,MATCH(Analysis!K$20,Dataset!$A$1:$L$1,0),0) -> Portugal, Spain | L23: =VLOOKUP($F23,Dataset!$A$1:$L$8808,MATCH(Analysis!L$20,Dataset!$A$1:$L$1,0),0) -> 42804 | M23: =VLOOKUP($F23,Dataset!$A$1:$L$8808,MATCH(Analysis!M$20,Dataset!$A$1:$L$1,0),0) -> 2016 | N23: =VLOOKUP($F23,Dataset!$A$1:$L$8808,MATCH(Analysis!N$20,Dataset!$A$1:$L$1,0),0) -> TV-MA | ... Q23: =VLOOKUP($F23,Dataset!$A$1:$L$8808,MATCH(Analysis!Q$20,Dataset!$A$1:$L$1,0),0) -> A man who is diagnosed with multiple sclerosis responds by training for an Ironman triathlon, with his cranky father-in-law's help.
F24: s8121 | G24: =VLOOKUP($F24,Dataset!$A$1:$L$8808,MATCH(Analysis!G$20,Dataset!$A$1:$L$1,0),0) -> Movie | H24: =VLOOKUP($F24,Dataset!$A$1:$L$8808,MATCH(Analysis!H$20,Dataset!$A$1:$L$1,0),0) -> Sunrise | I24: =VLOOKUP($F24,Dataset!$A$1:$L$8808,MATCH(Analysis!I$20,Dataset!$A$1:$L$1,0),0) -> Partho Sen-Gupta | J24: =VLOOKUP($F24,Dataset!$A$1:$L$8808,MATCH(Analysis!J$20,Dataset!$A$1:$L$1,0),0) -> Adil Hussain, Tannishtha Chatterjee, Gulnaaz Ansari, Komal Gupta, Esha Amlani, Ashalata Wabgaonkar, Hridaynath Jadhav, Chinmay Kambli, Nandini Bora, Komal Gawade | K24: =VLOOKUP($F24,Dataset!$A$1:$L$8808,MATCH(Analysis!K$20,Dataset!$A$1:$L$1,0),0) -> India, France | L24: =VLOOKUP($F24,Dataset!$A$1:$L$8808,MATCH(Analysis!L$20,Dataset!$A$1:$L$1,0),0) -> 42809 | M24: =VLOOKUP($F24,Dataset!$A$1:$L$8808,MATCH(Analysis!M$20,Dataset!$A$1:$L$1,0),0) -> 2014 | N24: =VLOOKUP($F24,Dataset!$A$1:$L$8808,MATCH(Analysis!N$20,Dataset!$A$1:$L$1,0),0) -> TV-MA | ... Q24: =VLOOKUP($F24,Dataset!$A$1:$L$8808,MATCH(Analysis!Q$20,Dataset!$A$1:$L$1,0),0) -> While investigating a child kidnapping, a Mumbai police inspector is haunted by a shadowy dream figure and memories of his own abducted daughter.
F25: s4197 | G25: =VLOOKUP($F25,Dataset!$A$1:$L$8808,MATCH(Analysis!G$20,Dataset!$A$1:$L$1,0),0) -> TV Show | H25: =VLOOKUP($F25,Dataset!$A$1:$L$8808,MATCH(Analysis!H$20,Dataset!$A$1:$L$1,0),0) -> La Grande ChaumiÃ¨re Violette | I25: =VLOOKUP($F25,Dataset!$A$1:$L$8808,MATCH(Analysis!I$20,Dataset!$A$1:$L$1,0),0) -> 0 | J25: =VLOOKUP($F25,Dataset!$A$1:$L$8808,MATCH(Analysis!J$20,Dataset!$A$1:$L$1,0),0) -> Eli Shi, Alice Ko, Jen-Shuo Cheng, Chiung-Hsuan Hsieh, Herb Hsu, Bryant Lee, Hsiu-Ling Lin, Ma Ju-lung, Ching-kuan Wang | K25: =VLOOKUP($F25,Dataset!$A$1:$L$8808,MATCH(Analysis!K$20,Dataset!$A$1:$L$1,0),0) -> Taiwan | L25: =VLOOKUP($F25,Dataset!$A$1:$L$8808,MATCH(Analysis!L$20,Dataset!$A$1:$L$1,0),0) -> 43479 | M25: =VLOOKUP($F25,Dataset!$A$1:$L$8808,MATCH(Analysis!M$20,Dataset!$A$1:$L$1,0),0) -> 2016 | N25: =VLOOKUP($F25,Dataset!$A$1:$L$8808,MATCH(Analysis!N$20,Dataset!$A$1:$L$1,0),0) -> TV-14 | ... Q25: =VLOOKUP($F25,Dataset!$A$1:$L$8808,MATCH(Analysis!Q$20,Dataset!$A$1:$L$1,0),0) -> Reminiscing about his youth in Taiwan's turbulent 1920s, Guo Xuehu reflects on his passion for art, a friendship with a painter â€“ and a doomed romance.
F31: Description and Highlights
